Workbook

Sheet Total Salary
B4: Player Value vs Salary for GSW Players in 2021-22 Season
B5: Player | C5: Real Salary | D5: Position | E5: Adj. Regular Season MRP | F5: Adj. Playoffs Season MRP | G5: Overpaid (Underpaid) | H5: Player Value
B6: Andrew Wiggins | C6: 31579390 | D6: F | E6: ='Regular Season'!D182 -> 8471307.8 | F6: ='Playoffs Season'!D182 -> 5497113.7 | G6: =C6-(E6+F6) -> 17610968 | H6: =E6+F6 -> 13968422
B7: Draymond Green | C7: 24026712 | D7: F | E7: ='Regular Season'!D187 -> 6229187 | F7: ='Playoffs Season'!D187 -> 4979329.7 | G7: =C7-(E7+F7) -> 12818195 | H7: =E7+F7 -> 11208517
B8: Jonathan Kuminga | C8: 5466360 | D8: F | E8: ='Regular Season'!D190 -> 2169819.3 | F8: ='Playoffs Season'!D190 -> 821830.57 | G8: =C8-(E8+F8) -> 2474710.1 | H8: =E8+F8 -> 2991649.9
B9: Juan Toscano-Anderson | C9: 2089448 | D9: F | E9: ='Regular Season'!D192 -> 2564359.7 | F9: ='Playoffs Season'!D192 -> 918035.54 | G9: =C9-(E9+F9) -> -1392947.2 | H9: =E9+F9 -> 3482395.2
B10: Damion Lee | C10: 1910860 | D10: G | E10: ='Regular Season'!D188 -> 2205387.5 | F10: ='Playoffs Season'!D188 -> 758282.11 | G10: =C10-(E10+F10) -> -1052809.6 | H10: =E10+F10 -> 2963669.6
B11: Gary Payton II | C11: 1939350 | D11: G | E11: ='Regular Season'!D189 -> 7440295.6 | F11: ='Playoffs Season'!D189 -> 2804394.8 | G11: =C11-(E11+F11) -> -8305340.4 | H11: =E11+F11 -> 10244690
B12: Klay Thompson | C12: 37980720 | D12: G | E12: ='Regular Season'!D193 -> 3262485.1 | F12: ='Playoffs Season'!D193 -> 1316550.4 | G12: =C12-(E12+F12) -> 33401684 | H12: =E12+F12 -> 4579035.5
B13: Kevon Looney | C13: 5178572 | D13: PF | E13: ='Regular Season'!D185 -> 6298363.1 | F13: ='Playoffs Season'!D185 -> 3153726.4 | G13: =C13-(E13+F13) -> -4273517.6 | H13: =E13+F13 -> 9452089.6
B14: Nemanja Bjelica | C14: 2089448 | D14: PF | E14: ='Regular Season'!D191 -> 3756571.7 | F14: ='Playoffs Season'!D191 -> 984207.25 | G14: =C14-(E14+F14) -> -2651330.9 | H14: =E14+F14 -> 4740778.9
B15: Stephen Curry | C15: 45780966 | D15: PG | E15: ='Regular Season'!D184 -> 13751135 | F15: ='Playoffs Season'!D184 -> 5476906.9 | G15: =C15-(E15+F15) -> 26552924 | H15: =E15+F15 -> 19228042
B16: Chris Chiozza | C16: 0 | D16: PG | E16: ='Regular Season'!D196 -> 135927.86 | F16: ='Playoffs Season'!D196 -> 0 | G16: =C16-(E16+F16) -> -135927.86 | H16: =E16+F16 -> 135927.86
B17: Jeff Dowtin | C17: 0 | D17: PG | E17: ='Regular Season'!D198 -> 1340541.3 | F17: ='Playoffs Season'!D198 -> 0 | G17: =C17-(E17+F17) -> -1340541.3 | H17: =E17+F17 -> 1340541.3
B18: Otto Porter Jr. | C18: 2389641 | D18: SF | E18: ='Regular Season'!D186 -> 6314992.8 | F18: ='Playoffs Season'!D186 -> 3074871.9 | G18: =C18-(E18+F18) -> -7000223.7 | H18: =E18+F18 -> 9389864.7
B19: Andre Iguodala | C19: 2641691 | D19: SF | E19: ='Regular Season'!D195 -> 4118235.3 | F19: ='Playoffs Season'!D195 -> 944583.16 | G19: =C19-(E19+F19) -> -2421127.5 | H19: =E19+F19 -> 5062818.5
B20: Jordan Poole | C20: 2161440 | D20: SG | E20: ='Regular Season'!D183 -> 7732091.7 | F20: ='Playoffs Season'!D183 -> 2125952.8 | G20: =C20-(E20+F20) -> -7696604.5 | H20: =E20+F20 -> 9858044.5
B21: Moses Moody | C21: 3562080 | D21: SG | E21: ='Regular Season'!D194 -> 692917.37 | F21: ='Playoffs Season'!D194 -> 1208841.3 | G21: =C21-(E21+F21) -> 1660321.3 | H21: =E21+F21 -> 1901758.7
B22: Quinndary Weatherspoon | C22: 95930 | D22: SG | E22: ='Regular Season'!D197 -> 1013209 | F22: ='Playoffs Season'!D197 -> 0 | G22: =C22-(E22+F22) -> -917279.03 | H22: =E22+F22 -> 1013209

Sheet Regular Season
B2: Raw Player Data Per 36 Minutes
B3: Player | C3: G | D3: GS | E3: 3PA | F3: 2PA | G3: FTA | H3: TRB | I3: AST | J3: STL | K3: BLK | L3: TOV | M3: PF | N3: PTS
B4: Andrew Wiggins | C4: 73 | D4: 73 | E4: 6.2 | F4: 9.6 | G4: 3.6 | H4: 5 | I4: 2.5 | J4: 1.2 | K4: 0.8 | L4: 1.7 | M4: 2.4 | N4: 19.4
B5: Jordan Poole | C5: 76 | D5: 51 | E5: 9.1 | F5: 7.5 | G5: 4.2 | H5: 4.1 | I5: 4.8 | J5: 0.9 | K5: 0.4 | L5: 2.9 | M5: 3.2 | N5: 22.2
B6: Stephen Curry | C6: 64 | D6: 64 | E6: 12.2 | F6: 7.7 | G6: 4.9 | H6: 5.5 | I6: 6.6 | J6: 1.4 | K6: 0.4 | L6: 3.4 | M6: 2.1 | N6: 26.5
B7: Kevon Looney | C7: 82 | D7: 80 | E7: 0 | F7: 7.5 | G7: 2.6 | H7: 12.4 | I7: 3.4 | J7: 1 | K7: 1.1 | L7: 1.4 | M7: 4.5 | N7: 10.2
B8: Otto Porter Jr. | C8: 63 | D8: 15 | E8: 5.6 | F8: 5.2 | G8: 1.6 | H8: 9.3 | I8: 2.4 | J8: 1.8 | K8: 0.7 | L8: 1 | M8: 2.1 | N8: 13.3
B9: Draymond Green | C9: 46 | D9: 44 | E9: 1.5 | F9: 5.5 | G9: 2.5 | H9: 9.1 | I9: 8.7 | J9: 1.7 | K9: 1.4 | L9: 3.8 | M9: 3.7 | N9: 9.4
B10: Damion Lee | C10: 63 | D10: 5 | E10: 5.4 | F10: 5.6 | G10: 2.1 | H10: 5.8 | I10: 1.8 | J10: 1.1 | K10: 0.2 | L10: 1.1 | M10: 2.7 | N10: 13.4
B11: Gary Payton II | C11: 71 | D11: 16 | E11: 3.5 | F11: 6.5 | G11: 1.7 | H11: 7.1 | I11: 1.8 | J11: 2.8 | K11: 0.6 | L11: 1.2 | M11: 3.8 | N11: 14.5
B12: Jonathan Kuminga | C12: 70 | D12: 12 | E12: 4.5 | F12: 9.4 | G12: 5.8 | H12: 7.1 | I12: 1.9 | J12: 0.9 | K12: 0.7 | L12: 2.2 | M12: 4.4 | N12: 19.8
B13: Nemanja Bjelica | C13: 71 | D13: 0 | E13: 4.7 | F13: 6.1 | G13: 2.6 | H13: 9.3 | I13: 5 | J13: 1.3 | K13: 0.8 | L13: 2.7 | M13: 4 | N13: 13.6
B14: Juan Toscano-Anderson | C14: 73 | D14: 6 | E14: 3.2 | F14: 5.4 | G14: 2.5 | H14: 6.4 | I14: 4.6 | J14: 1.7 | K14: 0.6 | L14: 2.5 | M14: 4.2 | N14: 10.8
B15: Klay Thompson | C15: 32 | D15: 32 | E15: 11.3 | F15: 10.6 | G15: 2 | H15: 4.8 | I15: 3.4 | J15: 0.6 | K15: 0.7 | L15: 1.6 | M15: 2.1 | N15: 24.9
... B20: Jeff Dowtin | C20: 4 | D20: 0 | E20: 1.3 | F20: 6.4 | G20: 0 | H20: 9 | I20: 3.9 | J20: 0 | K20: 1.3 | L20: 1.3 | M20: 2.6 | N20: 7.7
B22: Coefficients | C22: (GS/G)^2 | D22: PTS/36 | E22: TRB/36 | F22: AST/36 | G22: STL/36 | H22: BLK/36 | I22: TOV/36 | J22: PF/36 | K22: FTA/36 | L22: 2PA/36 | M22: 3PA/36 | N22: Intercept
B23: OPI Box | C23: 0.632 | D23: 1.144 | E23: 0.143 | F23: 0.705 | G23: 0.597 | H23: -0.013 | I23: -1.695 | J23: -0.059 | K23: -0.308 | L23: -0.91 | M23: -0.612 | N23: -5.621
B24: DPI Box | C24: 1.924 | D24: 0.049 | E24: 0.259 | F24: 0.192 | G24: 1.694 | H24: 1.393 | I24: -0.874 | J24: 0.251 | K24: 0.055 | L24: -0.191 | M24: -0.138 | N24: -3.521
B26: Sorted Player Data Per 36 Minutes
B27: Player | C27: (GS/G)^2 | D27: PTS/36 | E27: TRB/36 | F27: AST/36 | G27: STL/36 | H27: BLK/36 | I27: TOV/36 | J27: PF/36 | K27: FTA/36 | L27: 2PA/36 | M27: 3PA/36 | N27: Intercept
B28: Andrew Wiggins | C28: =(D4/C4)^2 -> 1 | D28: =N4 -> 19.4 | E28: =H4 -> 5 | F28: =I4 -> 2.5 | G28: =J4 -> 1.2 | H28: =K4 -> 0.8 | I28: =L4 -> 1.7 | J28: =M4 -> 2.4 | K28: =G4 -> 3.6 | L28: =F4 -> 9.6 | M28: =E4 -> 6.2 | N28: 1
B29: Jordan Poole | C29: =(D5/C5)^2 -> 0.45031163 | D29: =N5 -> 22.2 | E29: =H5 -> 4.1 | F29: =I5 -> 4.8 | G29: =J5 -> 0.9 | H29: =K5 -> 0.4 | I29: =L5 -> 2.9 | J29: =M5 -> 3.2 | K29: =G5 -> 4.2 | L29: =F5 -> 7.5 | M29: =E5 -> 9.1 | N29: 1
B30: Stephen Curry | C30: =(D6/C6)^2 -> 1 | D30: =N6 -> 26.5 | E30: =H6 -> 5.5 | F30: =I6 -> 6.6 | G30: =J6 -> 1.4 | H30: =K6 -> 0.4 | I30: =L6 -> 3.4 | J30: =M6 -> 2.1 | K30: =G6 -> 4.9 | L30: =F6 -> 7.7 | M30: =E6 -> 12.2 | N30: 1
B31: Kevon Looney | C31: =(D7/C7)^2 -> 0.9518144 | D31: =N7 -> 10.2 | E31: =H7 -> 12.4 | F31: =I7 -> 3.4 | G31: =J7 -> 1 | H31: =K7 -> 1.1 | I31: =L7 -> 1.4 | J31: =M7 -> 4.5 | K31: =G7 -> 2.6 | L31: =F7 -> 7.5 | M31: =E7 -> 0 | N31: 1
B32: Otto Porter Jr. | C32: =(D8/C8)^2 -> 0.056689342 | D32: =N8 -> 13.3 | E32: =H8 -> 9.3 | F32: =I8 -> 2.4 | G32: =J8 -> 1.8 | H32: =K8 -> 0.7 | I32: =L8 -> 1 | J32: =M8 -> 2.1 | K32: =G8 -> 1.6 | L32: =F8 -> 5.2 | M32: =E8 -> 5.6 | N32: 1
B33: Draymond Green | C33: =(D9/C9)^2 -> 0.91493384 | D33: =N9 -> 9.4 | E33: =H9 -> 9.1 | F33: =I9 -> 8.7 | G33: =J9 -> 1.7 | H33: =K9 -> 1.4 | I33: =L9 -> 3.8 | J33: =M9 -> 3.7 | K33: =G9 -> 2.5 | L33: =F9 -> 5.5 | M33: =E9 -> 1.5 | N33: 1
B34: Damion Lee | C34: =(D10/C10)^2 -> 0.0062988158 | D34: =N10 -> 13.4 | E34: =H10 -> 5.8 | F34: =I10 -> 1.8 | G34: =J10 -> 1.1 | H34: =K10 -> 0.2 | I34: =L10 -> 1.1 | J34: =M10 -> 2.7 | K34: =G10 -> 2.1 | L34: =F10 -> 5.6 | M34: =E10 -> 5.4 | N34: 1
B35: Gary Payton II | C35: =(D11/C11)^2 -> 0.050783575 | D35: =N11 -> 14.5 | E35: =H11 -> 7.1 | F35: =I11 -> 1.8 | G35: =J11 -> 2.8 | H35: =K11 -> 0.6 | I35: =L11 -> 1.2 | J35: =M11 -> 3.8 | K35: =G11 -> 1.7 | L35: =F11 -> 6.5 | M35: =E11 -> 3.5 | N35: 1
B36: Jonathan Kuminga | C36: =(D12/C12)^2 -> 0.029387755 | D36: =N12 -> 19.8 | E36: =H12 -> 7.1 | F36: =I12 -> 1.9 | G36: =J12 -> 0.9 | H36: =K12 -> 0.7 | I36: =L12 -> 2.2 | J36: =M12 -> 4.4 | K36: =G12 -> 5.8 | L36: =F12 -> 9.4 | M36: =E12 -> 4.5 | N36: 1
B37: Nemanja Bjelica | C37: =(D13/C13)^2 -> 0 | D37: =N13 -> 13.6 | E37: =H13 -> 9.3 | F37: =I13 -> 5 | G37: =J13 -> 1.3 | H37: =K13 -> 0.8 | I37: =L13 -> 2.7 | J37: =M13 -> 4 | K37: =G13 -> 2.6 | L37: =F13 -> 6.1 | M37: =E13 -> 4.7 | N37: 1
B38: Juan Toscano-Anderson | C38: =(D14/C14)^2 -> 0.0067554888 | D38: =N14 -> 10.8 | E38: =H14 -> 6.4 | F38: =I14 -> 4.6 | G38: =J14 -> 1.7 | H38: =K14 -> 0.6 | I38: =L14 -> 2.5 | J38: =M14 -> 4.2 | K38: =G14 -> 2.5 | L38: =F14 -> 5.4 | M38: =E14 -> 3.2 | N38: 1
B39: Klay Thompson | C39: =(D15/C15)^2 -> 1 | D39: =N15 -> 24.9 | E39: =H15 -> 4.8 | F39: =I15 -> 3.4 | G39: =J15 -> 0.6 | H39: =K15 -> 0.7 | I39: =L15 -> 1.6 | J39: =M15 -> 2.1 | K39: =G15 -> 2 | L39: =F15 -> 10.6 | M39: =E15 -> 11.3 | N39: 1
... B44: Jeff Dowtin | C44: =(D20/C20)^2 -> 0 | D44: =N20 -> 7.7 | E44: =H20 -> 9 | F44: =I20 -> 3.9 | G44: =J20 -> 0 | H44: =K20 -> 1.3 | I44: =L20 -> 1.3 | J44: =M20 -> 2.6 | K44: =G20 -> 0 | L44: =F20 -> 6.4 | M44: =E20 -> 1.3 | N44: 1
B46: O-PIPM Box
B47: Player | C47: (GS/G)^2 | D47: PTS/36 | E47: TRB/36 | F47: AST/36 | G47: STL/36 | H47: BLK/36 | I47: TOV/36 | J47: PF/36 | K47: FTA/36 | L47: 2PA/36 | M47: 3PA/36 | N47: Intercept | O47: O-PIPM Box Measures
B48: Andrew Wiggins | C48: =C$23*C28 -> 0.632 | D48: =D$23*D28 -> 22.1936 | E48: =E$23*E28 -> 0.715 | F48: =F$23*F28 -> 1.7625 | G48: =G$23*G28 -> 0.7164 | H48: =H$23*H28 -> -0.0104 | I48: =I$23*I28 -> -2.8815 | J48: =J$23*J28 -> -0.1416 | ... N48: =N$23*N28 -> -5.621 | O48: =SUM(C48:N48) -> 3.7258
B49: Jordan Poole | C49: =C$23*C29 -> 0.28459695 | D49: =D$23*D29 -> 25.3968 | E49: =E$23*E29 -> 0.5863 | F49: =F$23*F29 -> 3.384 | G49: =G$23*G29 -> 0.5373 | H49: =H$23*H29 -> -0.0052 | I49: =I$23*I29 -> -4.9155 | J49: =J$23*J29 -> -0.1888 | ... N49: =N$23*N29 -> -5.621 | O49: =SUM(C49:N49) -> 5.770697
B50: Stephen Curry | C50: =C$23*C30 -> 0.632 | D50: =D$23*D30 -> 30.316 | E50: =E$23*E30 -> 0.7865 | F50: =F$23*F30 -> 4.653 | G50: =G$23*G30 -> 0.8358 | H50: =H$23*H30 -> -0.0052 | I50: =I$23*I30 -> -5.763 | J50: =J$23*J30 -> -0.1239 | ... N50: =N$23*N30 -> -5.621 | O50: =SUM(C50:N50) -> 9.7276
B51: Kevon Looney | C51: =C$23*C31 -> 0.6015467 | D51: =D$23*D31 -> 11.6688 | E51: =E$23*E31 -> 1.7732 | F51: =F$23*F31 -> 2.397 | G51: =G$23*G31 -> 0.597 | H51: =H$23*H31 -> -0.0143 | I51: =I$23*I31 -> -2.373 | J51: =J$23*J31 -> -0.2655 | ... N51: =N$23*N31 -> -5.621 | O51: =SUM(C51:N51) -> 1.1379467
B52: Otto Porter Jr. | C52: =C$23*C32 -> 0.035827664 | D52: =D$23*D32 -> 15.2152 | E52: =E$23*E32 -> 1.3299 | F52: =F$23*F32 -> 1.692 | G52: =G$23*G32 -> 1.0746 | H52: =H$23*H32 -> -0.0091 | I52: =I$23*I32 -> -1.695 | J52: =J$23*J32 -> -0.1239 | ... N52: =N$23*N32 -> -5.621 | O52: =SUM(C52:N52) -> 3.2465277
...

Sheet Playoffs Season
B2: Raw Player Data Per 36 Minutes
B3: Player | C3: G | D3: GS | E3: 3PA | F3: 2PA | G3: FTA | H3: TRB | I3: AST | J3: STL | K3: BLK | L3: TOV | M3: PF | N3: PTS
B4: Andrew Wiggins | C4: 22 | D4: 22 | E4: 4.9 | F4: 9.4 | G4: 3.1 | H4: 7.7 | I4: 1.9 | J4: 1 | K4: 1.1 | L4: 1.4 | M4: 2.5 | N4: 17
B5: Jordan Poole | C5: 22 | D5: 5 | E5: 7.6 | F5: 7.5 | G5: 4.2 | H5: 3.7 | I5: 4.9 | J5: 1 | K5: 0.5 | L5: 3.1 | M5: 3.7 | N5: 22.2
B6: Stephen Curry | C6: 22 | D6: 18 | E6: 10.8 | F6: 9.9 | G6: 6.1 | H6: 5.4 | I6: 6.1 | J6: 1.4 | K6: 0.4 | L6: 2.7 | M6: 2.8 | N6: 28.4
B7: Kevon Looney | C7: 22 | D7: 13 | E7: 0 | F7: 7.1 | G7: 1.4 | H7: 13.5 | I7: 3.9 | J7: 0.7 | K7: 0.8 | L7: 1.5 | M7: 4 | N7: 10.2
B8: Otto Porter Jr. | C8: 19 | D8: 3 | E8: 4.6 | F8: 2.9 | G8: 0.9 | H8: 6.3 | I8: 3.3 | J8: 1.6 | K8: 0.6 | L8: 1.2 | M8: 3.3 | N8: 9.9
B9: Draymond Green | C9: 22 | D9: 22 | E9: 2 | F9: 5.4 | G9: 2.4 | H9: 8.1 | I9: 7.1 | J9: 1.3 | K9: 1.1 | L9: 3 | M9: 4.5 | N9: 9
B10: Damion Lee | C10: 16 | D10: 0 | E10: 4.6 | F10: 5.2 | G10: 0.9 | H10: 7.5 | I10: 2 | J10: 0.3 | K10: 0 | L10: 1.7 | M10: 2.3 | N10: 9.3
B11: Gary Payton II | C11: 12 | D11: 2 | E11: 2.7 | F11: 5.1 | G11: 3.2 | H11: 6.6 | I11: 2.8 | J11: 2.5 | K11: 1.2 | L11: 1.1 | M11: 4.1 | N11: 13.8
B12: Jonathan Kuminga | C12: 16 | D12: 3 | E12: 3.4 | F12: 12.3 | G12: 6.8 | H12: 7 | I12: 2.1 | J12: 0.8 | K12: 0.5 | L12: 2.9 | M12: 2.9 | N12: 21.7
B13: Nemanja Bjelica | C13: 15 | D13: 0 | E13: 1.9 | F13: 6.2 | G13: 1.7 | H13: 7.4 | I13: 4.1 | J13: 1 | K13: 0.5 | L13: 1.7 | M13: 5 | N13: 10.3
B14: Juan Toscano-Anderson | C14: 14 | D14: 0 | E14: 3.7 | F14: 3.7 | G14: 2.2 | H14: 7.3 | I14: 5.9 | J14: 1.5 | K14: 0.7 | L14: 5.9 | M14: 2.2 | N14: 8.1
B15: Klay Thompson | C15: 22 | D15: 22 | E15: 9.1 | F15: 7.6 | G15: 1.4 | H15: 3.9 | I15: 2.3 | J15: 1.1 | K15: 0.7 | L15: 1.3 | M15: 2.1 | N15: 19
... B20: Jeff Dowtin | C20: 0 | D20: 0 | E20: 0 | F20: 0 | G20: 0 | H20: 0 | I20: 0 | J20: 0 | K20: 0 | L20: 0 | M20: 0 | N20: 0
B22: Coefficients | C22: (GS/G)^2 | D22: PTS/36 | E22: TRB/36 | F22: AST/36 | G22: STL/36 | H22: BLK/36 | I22: TOV/36 | J22: PF/36 | K22: FTA/36 | L22: 2PA/36 | M22: 3PA/36 | N22: Intercept
B23: OPI Box | C23: 0.632 | D23: 1.144 | E23: 0.143 | F23: 0.705 | G23: 0.597 | H23: -0.013 | I23: -1.695 | J23: -0.059 | K23: -0.308 | L23: -0.91 | M23: -0.612 | N23: -5.621
B24: DPI Box | C24: 1.924 | D24: 0.049 | E24: 0.259 | F24: 0.192 | G24: 1.694 | H24: 1.393 | I24: -0.874 | J24: 0.251 | K24: 0.055 | L24: -0.191 | M24: -0.138 | N24: -3.521
B26: Sorted Player Data Per 36 Minutes
B27: Player | C27: (GS/G)^2 | D27: PTS/36 | E27: TRB/36 | F27: AST/36 | G27: STL/36 | H27: BLK/36 | I27: TOV/36 | J27: PF/36 | K27: FTA/36 | L27: 2PA/36 | M27: 3PA/36 | N27: Intercept
B28: Andrew Wiggins | C28: =(D4/C4)^2 -> 1 | D28: =N4 -> 17 | E28: =H4 -> 7.7 | F28: =I4 -> 1.9 | G28: =J4 -> 1 | H28: =K4 -> 1.1 | I28: =L4 -> 1.4 | J28: =M4 -> 2.5 | K28: =G4 -> 3.1 | L28: =F4 -> 9.4 | M28: =E4 -> 4.9 | N28: 1
B29: Jordan Poole | C29: =(D5/C5)^2 -> 0.051652893 | D29: =N5 -> 22.2 | E29: =H5 -> 3.7 | F29: =I5 -> 4.9 | G29: =J5 -> 1 | H29: =K5 -> 0.5 | I29: =L5 -> 3.1 | J29: =M5 -> 3.7 | K29: =G5 -> 4.2 | L29: =F5 -> 7.5 | M29: =E5 -> 7.6 | N29: 1
B30: Stephen Curry | C30: =(D6/C6)^2 -> 0.66942149 | D30: =N6 -> 28.4 | E30: =H6 -> 5.4 | F30: =I6 -> 6.1 | G30: =J6 -> 1.4 | H30: =K6 -> 0.4 | I30: =L6 -> 2.7 | J30: =M6 -> 2.8 | K30: =G6 -> 6.1 | L30: =F6 -> 9.9 | M30: =E6 -> 10.8 | N30: 1
B31: Kevon Looney | C31: =(D7/C7)^2 -> 0.34917355 | D31: =N7 -> 10.2 | E31: =H7 -> 13.5 | F31: =I7 -> 3.9 | G31: =J7 -> 0.7 | H31: =K7 -> 0.8 | I31: =L7 -> 1.5 | J31: =M7 -> 4 | K31: =G7 -> 1.4 | L31: =F7 -> 7.1 | M31: =E7 -> 0 | N31: 1
B32: Otto Porter Jr. | C32: =(D8/C8)^2 -> 0.024930748 | D32: =N8 -> 9.9 | E32: =H8 -> 6.3 | F32: =I8 -> 3.3 | G32: =J8 -> 1.6 | H32: =K8 -> 0.6 | I32: =L8 -> 1.2 | J32: =M8 -> 3.3 | K32: =G8 -> 0.9 | L32: =F8 -> 2.9 | M32: =E8 -> 4.6 | N32: 1
B33: Draymond Green | C33: =(D9/C9)^2 -> 1 | D33: =N9 -> 9 | E33: =H9 -> 8.1 | F33: =I9 -> 7.1 | G33: =J9 -> 1.3 | H33: =K9 -> 1.1 | I33: =L9 -> 3 | J33: =M9 -> 4.5 | K33: =G9 -> 2.4 | L33: =F9 -> 5.4 | M33: =E9 -> 2 | N33: 1
B34: Damion Lee | C34: =(D10/C10)^2 -> 0 | D34: =N10 -> 9.3 | E34: =H10 -> 7.5 | F34: =I10 -> 2 | G34: =J10 -> 0.3 | H34: =K10 -> 0 | I34: =L10 -> 1.7 | J34: =M10 -> 2.3 | K34: =G10 -> 0.9 | L34: =F10 -> 5.2 | M34: =E10 -> 4.6 | N34: 1
B35: Gary Payton II | C35: =(D11/C11)^2 -> 0.027777778 | D35: =N11 -> 13.8 | E35: =H11 -> 6.6 | F35: =I11 -> 2.8 | G35: =J11 -> 2.5 | H35: =K11 -> 1.2 | I35: =L11 -> 1.1 | J35: =M11 -> 4.1 | K35: =G11 -> 3.2 | L35: =F11 -> 5.1 | M35: =E11 -> 2.7 | N35: 1
B36: Jonathan Kuminga | C36: =(D12/C12)^2 -> 0.03515625 | D36: =N12 -> 21.7 | E36: =H12 -> 7 | F36: =I12 -> 2.1 | G36: =J12 -> 0.8 | H36: =K12 -> 0.5 | I36: =L12 -> 2.9 | J36: =M12 -> 2.9 | K36: =G12 -> 6.8 | L36: =F12 -> 12.3 | M36: =E12 -> 3.4 | N36: 1
B37: Nemanja Bjelica | C37: =(D13/C13)^2 -> 0 | D37: =N13 -> 10.3 | E37: =H13 -> 7.4 | F37: =I13 -> 4.1 | G37: =J13 -> 1 | H37: =K13 -> 0.5 | I37: =L13 -> 1.7 | J37: =M13 -> 5 | K37: =G13 -> 1.7 | L37: =F13 -> 6.2 | M37: =E13 -> 1.9 | N37: 1
B38: Juan Toscano-Anderson | C38: =(D14/C14)^2 -> 0 | D38: =N14 -> 8.1 | E38: =H14 -> 7.3 | F38: =I14 -> 5.9 | G38: =J14 -> 1.5 | H38: =K14 -> 0.7 | I38: =L14 -> 5.9 | J38: =M14 -> 2.2 | K38: =G14 -> 2.2 | L38: =F14 -> 3.7 | M38: =E14 -> 3.7 | N38: 1
B39: Klay Thompson | C39: =(D15/C15)^2 -> 1 | D39: =N15 -> 19 | E39: =H15 -> 3.9 | F39: =I15 -> 2.3 | G39: =J15 -> 1.1 | H39: =K15 -> 0.7 | I39: =L15 -> 1.3 | J39: =M15 -> 2.1 | K39: =G15 -> 1.4 | L39: =F15 -> 7.6 | M39: =E15 -> 9.1 | N39: 1
... B41: Andre Iguodala | C41: =(D17/C17)^2 -> 0 | D41: =N17 -> 6.5 | E41: =H17 -> 4.1 | F41: =I17 -> 7.1 | G41: =J17 -> 0 | H41: =K17 -> 1.2 | I41: =L17 -> 2.4 | J41: =M17 -> 6.5 | K41: =G17 -> 1.8 | L41: =F17 -> 3.5 | M41: =E17 -> 1.8 | N41: 1
B42: Chris Chiozza | C42: 0 | D42: =N18 -> 0 | E42: =H18 -> 0 | F42: =I18 -> 0 | G42: =J18 -> 0 | H42: =K18 -> 0 | I42: =L18 -> 0 | J42: =M18 -> 0 | K42: =G18 -> 0 | L42: =F18 -> 0 | M42: =E18 -> 0 | N42: 0
B43: Quinndary Weatherspoon | C43: 0 | D43: =N19 -> 0 | E43: =H19 -> 0 | F43: =I19 -> 0 | G43: =J19 -> 0 | H43: =K19 -> 0 | I43: =L19 -> 0 | J43: =M19 -> 0 | K43: =G19 -> 0 | L43: =F19 -> 0 | M43: =E19 -> 0 | N43: 0
B44: Jeff Dowtin | C44: 0 | D44: =N20 -> 0 | E44: =H20 -> 0 | F44: =I20 -> 0 | G44: =J20 -> 0 | H44: =K20 -> 0 | I44: =L20 -> 0 | J44: =M20 -> 0 | K44: =G20 -> 0 | L44: =F20 -> 0 | M44: =E20 -> 0 | N44: 0
B46: O-PIPM Box
B47: Player | C47: (GS/G)^2 | D47: PTS/36 | E47: TRB/36 | F47: AST/36 | G47: STL/36 | H47: BLK/36 | I47: TOV/36 | J47: PF/36 | K47: FTA/36 | L47: 2PA/36 | M47: 3PA/36 | N47: Intercept | O47: O-PIPM Box Measures
B48: Andrew Wiggins | C48: =C$23*C28 -> 0.632 | D48: =D$23*D28 -> 19.448 | E48: =E$23*E28 -> 1.1011 | F48: =F$23*F28 -> 1.3395 | G48: =G$23*G28 -> 0.597 | H48: =H$23*H28 -> -0.0143 | I48: =I$23*I28 -> -2.373 | J48: =J$23*J28 -> -0.1475 | ... N48: =N$23*N28 -> -5.621 | O48: =SUM(C48:N48) -> 2.4542
B49: Jordan Poole | C49: =C$23*C29 -> 0.032644628 | D49: =D$23*D29 -> 25.3968 | E49: =E$23*E29 -> 0.5291 | F49: =F$23*F29 -> 3.4545 | G49: =G$23*G29 -> 0.597 | H49: =H$23*H29 -> -0.0065 | I49: =I$23*I29 -> -5.2545 | J49: =J$23*J29 -> -0.2183 | ... N49: =N$23*N29 -> -5.621 | O49: =SUM(C49:N49) -> 6.1399446
...
